Workbook

Sheet Cover
A1: EV Charging Station Feasibility - Delhi vs Hyderabad
A2: Portfolio feasibility study for a hypothetical charge-point operator. Not a real client engagement.
A4: Decision question
A5: Should a CPO invest in one public EV charging station (rented site, 10 years) in Delhi, Hyderabad, both or neither - and under what conditions?
A7: Key outputs (base case, live links)
A8: Delhi NPV (Rs) | B8: =Scenarios!C10
A9: Delhi IRR | B9: =Scenarios!C11
A10: Hyderabad NPV (Rs) | B10: =Scenarios!F10
A11: Hyderabad IRR | B11: =Scenarios!F11
A12: Delhi year-1 utilisation | B12: =Scenarios!C4
A13: Hyderabad year-1 utilisation | B13: =Scenarios!F4
A15: How to use
A16: Blue cells = inputs (change on the Inputs sheet only). Black = formulas. Green = links between sheets. Yellow = key levers.
A17: Six model sheets: DEL_/HYD_ x Cons/Base/Aggr. Each is the same formula layout reading its own scenario column.
A18: Levers on Inputs (grid work factor, staff override, host share override) reproduce the 'what would it take' case.
A19: Checks sheet must show ALL CHECKS PASS = TRUE.
A20: Sources for every number: docs/source_register.md in the repository.

Sheet Inputs
A1: INPUTS - every assumption used by the model (blue = input you can change)
A3: CONTROLS
A4: Charger configuration (A / B / C) | C4: A | K4: A = lean, B = balanced, C = fleet hub; A has the highest NPV in both cities
A5: Demand factor | C5: 1 | K5: Multiply demand (1 = as per scenario)
A6: Price factor | C6: 1 | K6: Multiply charging price (1 = as per scenario)
A7: Electricity cost factor | C7: 1 | K7: Multiply electricity tariff
A8: CAPEX factor | C8: 1 | K8: Multiply equipment + civil + grid CAPEX
A9: Grid work factor (1 = new connection, 0 = host's spare capacity) | C9: 1 | K9: Lever: host site already has spare grid capacity
A10: Staff FTE override (blank = scenario value) | K10: Lever: 0 = unmanned remote-monitored
A11: Host revenue share override (blank = scenario value) | K11: Lever: negotiated share
A12: Discount rate override (blank = CAPM) | K12: Tested 12%-16%
A14: Parameter | B14: Unit | C14: Delhi Cons | D14: Delhi Base | E14: Delhi Aggr | F14: Hyd Cons | G14: Hyd Base | H14: Hyd Aggr | I14: Label | J14: Source / rationale
A15: public_demand_kwh_per_day | B15: kWh/day | C15: 41641 | D15: 41641 | E15: 41641 | F15: 38471 | G15: 38471 | H15: 38471 | I15: DERIVED | J15: Phase 4 SAM 14,042 MWh/yr / 365 | Phase 4 SAM 15,199 MWh/yr / 365
A16: fast_stations | B16: stations | C16: 399 | D16: 399 | E16: 399 | F16: 373 | G16: 373 | H16: 373 | I16: DERIVED / FACT | J16: PIB Lok Sabha reply 16 Dec 2025 | Telangana 548 x 68% Hyderabad share (Phase 4)
A17: capture_multiple | B17: x fair share | C17: 0.75 | D17: 1.25 | E17: 2 | F17: 0.75 | G17: 1.25 | H17: 2 | I17: ASSUMPTION | J17: 1.0 = average existing station. Base 1.25 for a well-chosen, reliable site (many rivals seen faulted, Phase 5); 2.0 = hub-quality site
A18: year1_ramp | B18: share of steady demand | C18: 0.6 | D18: 0.7 | E18: 0.8 | F18: 0.6 | G18: 0.7 | H18: 0.8 | I18: ASSUMPTION | J18: New stations take time to be discovered by drivers and apps
A19: demand_growth_per_station | B19: per year | C19: 0 | D19: 0.07 | E19: 0.12 | F19: 0 | G19: 0.07 | H19: 0.12 | I19: ASSUMPTION | J19: EV stock doubling (Phase 4) but charger supply also surging (Delhi 16k points by end-2026; TGREDCO 200 stations), so per-station growth is modest
A20: kwh_per_session | B20: kWh | C20: 20 | D20: 20 | E20: 20 | F20: 20 | G20: 20 | H20: 20 | I20: ASSUMPTION | J20: Cab mid-shift top-up on ~26-30 kWh batteries; converts energy to sessions only
A21: price_net_of_gst | B21: Rs/kWh | C21: 16.94 | D21: 18.64 | E21: 19.06 | F21: 13 | G21: 16 | H21: 18.64 | I21: ASSUMPTION / DERIVED | J21: Cons = match TGREDCO Rs 13 excl GST; base = discount to private Rs 21.99 to compete with govt network; aggr = private median | Observed Rs 19.99 / 21.99 / 22.49 (Phase 5), assumed to include 18% GST
A22: price_escalation | B22: per year | C22: 0 | D22: 0.02 | E22: 0.03 | F22: 0 | G22: 0.02 | H22: 0.03 | I22: ASSUMPTION | J22: Cons 0% because TGREDCO price is fixed for 10 years | Prices have been flat; modest pass-through of tariff increases
A23: electricity_rs_per_kwh | B23: Rs/kWh | C23: 6 | D23: 5.5 | E23: 4.95 | F23: 6.5 | G23: 6 | H23: 6 | I23: DERIVED / FACT/ASSUMPTION | J23: DERC Rs 4.50 + PPAC 16-18% + surcharges/duty (applicability to verify) | TGERC LT-IX Rs 6.00; cons +Rs 0.50 for duty/FSA (to verify)
A24: electricity_fixed_rs_per_month | B24: Rs/month | C24: 0 | D24: 0 | E24: 0 | F24: 120 | G24: 120 | H24: 120 | I24: FACT | J24: DERC EV category: no fixed charge | TGERC LT-IX customer charge (HT config handled separately)
A25: tariff_escalation | B25: per year | C25: 0.05 | D25: 0.03 | E25: 0.02 | F25: 0.05 | G25: 0.03 | H25: 0.02 | I25: ASSUMPTION | J25: Tariffs frozen in FY27 in Telangana; Delhi order unchanged since FY22; range allows catch-up
A26: grid_losses | B26: share | C26: 0.03 | D26: 0.03 | E26: 0.03 | F26: 0.03 | G26: 0.03 | H26: 0.03 | I26: ASSUMPTION | J26: Charger/cable conversion losses: energy bought = energy sold / (1 - losses)
... A46: beta | B46: x | C46: 1 | D46: 1 | E46: 1 | F46: 1 | G46: 1 | H46: 1 | I46: ASSUMPTION | J46: No listed pure-play Indian CPO; market-average risk; tested 12-16%
A48: UNIT COSTS
A49: Item | B49: Unit | C49: Cost (Rs) | I49: Label | J49: Source / rationale
A50: dc_60kw_charger | B50: per unit | C50: 814000 | I50: DERIVED | J50: Linear interpolation of MHI benchmarks: 50 kW Rs 7.25 lakh, 100 kW Rs 11.68 lakh
A51: dc_120kw_charger | B51: per unit | C51: 1345000 | I51: DERIVED | J51: Linear extrapolation of the same MHI benchmarks (no 120 kW benchmark published)
A52: ac_7kw_charger | B52: per unit | C52: 58000 | I52: OBSERVED | J52: RIOD PowerPod Go 7.4 kW OCPP commercial charger listing (taxes included)
A53: civil_per_dc_bay | B53: per DC charger | C53: 200000 | I53: ESTIMATE | J53: Cars24 (Jun 2026): installation & civil Rs 1.5-2.0 lakh for a 30 kW station (upper end)
A54: civil_per_ac_bay | B54: per AC charger | C54: 50000 | I54: ASSUMPTION | J54: Smaller foundation and cabling than a DC bay
A55: signage | B55: per station | C55: 40000 | I55: ESTIMATE | J55: Cars24: Rs 25,000-40,000
A56: software_setup | B56: per station | C56: 35000 | I56: ESTIMATE | J56: Cars24: Rs 20,000-35,000
A57: permits_misc | B57: per station | C57: 50000 | I57: ESTIMATE | J57: Cars24: Rs 25,000-50,000
A58: hyd_ht_demand_charge | B58: Rs per kVA per month | C58: 100 | I58: FACT | J58: TGERC HT-IX (only if connected load > 150 kW)
A59: hyd_ht_customer_charge | B59: Rs per month | C59: 2000 | I59: FACT | J59: TGERC HT-IX at 11 kV
A61: CHARGER CONFIGURATIONS
A62: Config | B62: Description | C62: 60 kW DC units | D62: 120 kW DC units | E62: 7.4 kW AC units | F62: Grid band | G62: Grid work (Rs lakh) | I62: Label | J62: Source
A63: A | B63: Lean: 1 x 60 kW DC + 2 x 7.4 kW AC | C63: 1 | D63: 0 | E63: 2 | F63: <=100 kW | G63: 14.8 | I63: FACT | J63: MHI PM E-DRIVE Table 3
...

Sheet Scenarios
A1: SCENARIO COMPARISON - live links to the six model sheets
A3: Metric | B3: Delhi Cons | C3: Delhi Base | D3: Delhi Aggr | E3: Hyd Cons | F3: Hyd Base | G3: Hyd Aggr
A4: Year-1 utilisation | B4: ='DEL_Cons'!C65 | C4: ='DEL_Base'!C65 | D4: ='DEL_Aggr'!C65 | E4: ='HYD_Cons'!C65 | F4: ='HYD_Base'!C65 | G4: ='HYD_Aggr'!C65
A5: Year-5 utilisation | B5: ='DEL_Cons'!C66 | C5: ='DEL_Base'!C66 | D5: ='DEL_Aggr'!C66 | E5: ='HYD_Cons'!C66 | F5: ='HYD_Base'!C66 | G5: ='HYD_Aggr'!C66
A6: Year-1 revenue (Rs) | B6: ='DEL_Cons'!C67 | C6: ='DEL_Base'!C67 | D6: ='DEL_Aggr'!C67 | E6: ='HYD_Cons'!C67 | F6: ='HYD_Base'!C67 | G6: ='HYD_Aggr'!C67
A7: Year-1 EBITDA (Rs) | B7: ='DEL_Cons'!C68 | C7: ='DEL_Base'!C68 | D7: ='DEL_Aggr'!C68 | E7: ='HYD_Cons'!C68 | F7: ='HYD_Base'!C68 | G7: ='HYD_Aggr'!C68
A8: Year-5 EBITDA (Rs) | B8: ='DEL_Cons'!C69 | C8: ='DEL_Base'!C69 | D8: ='DEL_Aggr'!C69 | E8: ='HYD_Cons'!C69 | F8: ='HYD_Base'!C69 | G8: ='HYD_Aggr'!C69
A9: Year-5 EBITDA margin | B9: ='DEL_Cons'!C70 | C9: ='DEL_Base'!C70 | D9: ='DEL_Aggr'!C70 | E9: ='HYD_Cons'!C70 | F9: ='HYD_Base'!C70 | G9: ='HYD_Aggr'!C70
A10: NPV (Rs) | B10: ='DEL_Cons'!C62 | C10: ='DEL_Base'!C62 | D10: ='DEL_Aggr'!C62 | E10: ='HYD_Cons'!C62 | F10: ='HYD_Base'!C62 | G10: ='HYD_Aggr'!C62
A11: IRR | B11: ='DEL_Cons'!C63 | C11: ='DEL_Base'!C63 | D11: ='DEL_Aggr'!C63 | E11: ='HYD_Cons'!C63 | F11: ='HYD_Base'!C63 | G11: ='HYD_Aggr'!C63
A12: Payback (years) | B12: ='DEL_Cons'!C64 | C12: ='DEL_Base'!C64 | D12: ='DEL_Aggr'!C64 | E12: ='HYD_Cons'!C64 | F12: ='HYD_Base'!C64 | G12: ='HYD_Aggr'!C64
A13: EBITDA break-even utilisation (yr 1) | B13: ='DEL_Cons'!C75 | C13: ='DEL_Base'!C75 | D13: ='DEL_Aggr'!C75 | E13: ='HYD_Cons'!C75 | F13: ='HYD_Base'!C75 | G13: ='HYD_Aggr'!C75
A14: EBITDA break-even sessions/day (yr 1) | B14: ='DEL_Cons'!C74 | C14: ='DEL_Base'!C74 | D14: ='DEL_Aggr'!C74 | E14: ='HYD_Cons'!C74 | F14: ='HYD_Base'!C74 | G14: ='HYD_Aggr'!C74
A16: NPV break-even utilisation (from Python bisection; Excel has no goal-seek in a static file)
A17: NPV break-even utilisation (blank = not reachable within capacity) | C17: 0.2553 | D17: 0.1597 | F17: 0.3583 | G17: 0.1818

Sheet Sensitivity
A1: SENSITIVITY - NPV (Rs lakh), base case, one input changed at a time
A2: Values come from src/run_results.py. To reproduce any row live: set the matching factor on the Inputs sheet (e.g. Demand factor = 0.7) and read NPV on DEL_Base / HYD_Base.
A4: City | B4: Input tested | C4: Base NPV | D4: NPV worse | E4: NPV better | F4: Swing
A5: Delhi | B5: Staff 2 FTE / 0 FTE | C5: -25.39 | D5: -40.43 | E5: -11.7 | F5: 28.73
A6: Delhi | B6: Demand (capture) -30% / +30% | C6: -25.39 | D6: -34.95 | E6: -16.23 | F6: 18.72
A7: Delhi | B7: Grid work: new connection / host's spare capacity | C7: -25.39 | D7: -25.39 | E7: -8.76 | F7: 16.64
A8: Delhi | B8: CAPEX +20% / -20% | C8: -25.39 | D8: -32.13 | E8: -18.66 | F8: 13.46
A9: Delhi | B9: Charging price -10% / +10% | C9: -25.39 | D9: -30.55 | E9: -20.23 | F9: 10.32
A10: Delhi | B10: Electricity cost +20% / -20% | C10: -25.39 | D10: -29.34 | E10: -21.45 | F10: 7.9
A11: Delhi | B11: Host revenue share 20% / 10% | C11: -25.39 | D11: -28.51 | E11: -22.28 | F11: 6.23
A12: Delhi | B12: Discount rate 16% / 12% | C12: -25.39 | D12: -26.09 | E12: -24.5 | F12: 1.6
A13: Hyderabad | B13: Staff 2 FTE / 0 FTE | C13: -34.85 | D13: -49.88 | E13: -19.82 | F13: 30.07
A14: Hyderabad | B14: Grid work: new connection / host's spare capacity | C14: -34.85 | D14: -34.85 | E14: -18.06 | F14: 16.79
A15: Hyderabad | B15: Demand (capture) -30% / +30% | C15: -34.85 | D15: -41.59 | E15: -28.1 | F15: 13.49
A16: Hyderabad | B16: CAPEX +20% / -20% | C16: -34.85 | D16: -41.58 | E16: -28.12 | F16: 13.46
... A20: Hyderabad | B20: Discount rate 16% / 12% | C20: -34.85 | D20: -34.77 | E20: -34.94 | F20: -0.18
A23: WHAT WOULD IT TAKE? Controllable levers stacked on the base case (Rs lakh)
A24: City | B24: Step | C24: CAPEX | D24: NPV | E24: IRR % | F24: Payback yrs
A25: Delhi | B25: Base case | C25: 31.18 | D25: -25.39
A26: Delhi | B26: + host site with spare grid capacity | C26: 14.9 | D26: -8.76 | E26: 1.4 | F26: 9.5
A27: Delhi | B27: + unmanned (remote-monitored) | C27: 14.9 | D27: 2.94 | E27: 18 | F27: 5.1
A28: Delhi | B28: + host share cut to 10% | C28: 14.9 | D28: 5.27 | E28: 20.9 | F28: 4.7
A29: Delhi | B29: Break-even utilisation with all levers (%) | D29: 10.38
A30: Hyderabad | B30: Base case | C30: 31.18 | D30: -34.85
A31: Hyderabad | B31: + host site with spare grid capacity | C31: 14.9 | D31: -18.06
A32: Hyderabad | B32: + unmanned (remote-monitored) | C32: 14.9 | D32: -4.17 | E32: 7.8 | F32: 7.4
A33: Hyderabad | B33: + host share cut to 10% | C33: 14.9 | D33: -2.17 | E33: 11 | F33: 6.5
A34: Hyderabad | B34: Break-even utilisation with all levers (%) | D34: 14.33

Sheet Checks
A1: MODEL CHECKS - every row must read TRUE
A3: DEL_Cons: sold kWh never exceeds capacity | B3: =MAX('DEL_Cons'!D33:M33)<='DEL_Cons'!C17+0.001
A4: DEL_Cons: revenue = kWh x price (year 1) | B4: =ABS('DEL_Cons'!D37-'DEL_Cons'!D36*'DEL_Cons'!C21)<1
A5: DEL_Cons: EBITDA = gross profit - opex (year 5) | B5: =ABS('DEL_Cons'!H48-('DEL_Cons'!H39-'DEL_Cons'!H47))<1
A6: DEL_Cons: cumulative cash = sum of net cash flows | B6: =ABS('DEL_Cons'!M58-SUM('DEL_Cons'!C57:M57))<1
A7: DEL_Cons: Excel NPV matches Python NPV (config A, all factors = 1) within Rs 1,000 | B7: =OR(Inputs!$C$4<>"A",ABS('DEL_Cons'!C62--7082000.00)<1000)
A8: DEL_Base: sold kWh never exceeds capacity | B8: =MAX('DEL_Base'!D33:M33)<='DEL_Base'!C17+0.001
A9: DEL_Base: revenue = kWh x price (year 1) | B9: =ABS('DEL_Base'!D37-'DEL_Base'!D36*'DEL_Base'!C21)<1
A10: DEL_Base: EBITDA = gross profit - opex (year 5) | B10: =ABS('DEL_Base'!H48-('DEL_Base'!H39-'DEL_Base'!H47))<1
A11: DEL_Base: cumulative cash = sum of net cash flows | B11: =ABS('DEL_Base'!M58-SUM('DEL_Base'!C57:M57))<1
A12: DEL_Base: Excel NPV matches Python NPV (config A, all factors = 1) within Rs 1,000 | B12: =OR(Inputs!$C$4<>"A",ABS('DEL_Base'!C62--2539000.00)<1000)
A13: DEL_Aggr: sold kWh never exceeds capacity | B13: =MAX('DEL_Aggr'!D33:M33)<='DEL_Aggr'!C17+0.001
A14: DEL_Aggr: revenue = kWh x price (year 1) | B14: =ABS('DEL_Aggr'!D37-'DEL_Aggr'!D36*'DEL_Aggr'!C21)<1
A15: DEL_Aggr: EBITDA = gross profit - opex (year 5) | B15: =ABS('DEL_Aggr'!H48-('DEL_Aggr'!H39-'DEL_Aggr'!H47))<1
A16: DEL_Aggr: cumulative cash = sum of net cash flows | B16: =ABS('DEL_Aggr'!M58-SUM('DEL_Aggr'!C57:M57))<1
A17: DEL_Aggr: Excel NPV matches Python NPV (config A, all factors = 1) within Rs 1,000 | B17: =OR(Inputs!$C$4<>"A",ABS('DEL_Aggr'!C62-2255000.00)<1000)
A18: HYD_Cons: sold kWh never exceeds capacity | B18: =MAX('HYD_Cons'!D33:M33)<='HYD_Cons'!C17+0.001
A19: HYD_Cons: revenue = kWh x price (year 1) | B19: =ABS('HYD_Cons'!D37-'HYD_Cons'!D36*'HYD_Cons'!C21)<1
A20: HYD_Cons: EBITDA = gross profit - opex (year 5) | B20: =ABS('HYD_Cons'!H48-('HYD_Cons'!H39-'HYD_Cons'!H47))<1
A21: HYD_Cons: cumulative cash = sum of net cash flows | B21: =ABS('HYD_Cons'!M58-SUM('HYD_Cons'!C57:M57))<1
A22: HYD_Cons: Excel NPV matches Python NPV (config A, all factors = 1) within Rs 1,000 | B22: =OR(Inputs!$C$4<>"A",ABS('HYD_Cons'!C62--7606000.00)<1000)
A23: HYD_Base: sold kWh never exceeds capacity | B23: =MAX('HYD_Base'!D33:M33)<='HYD_Base'!C17+0.001
A24: HYD_Base: revenue = kWh x price (year 1) | B24: =ABS('HYD_Base'!D37-'HYD_Base'!D36*'HYD_Base'!C21)<1
A25: HYD_Base: EBITDA = gross profit - opex (year 5) | B25: =ABS('HYD_Base'!H48-('HYD_Base'!H39-'HYD_Base'!H47))<1
A26: HYD_Base: cumulative cash = sum of net cash flows | B26: =ABS('HYD_Base'!M58-SUM('HYD_Base'!C57:M57))<1
A27: HYD_Base: Excel NPV matches Python NPV (config A, all factors = 1) within Rs 1,000 | B27: =OR(Inputs!$C$4<>"A",ABS('HYD_Base'!C62--3485000.00)<1000)
A28: HYD_Aggr: sold kWh never exceeds capacity | B28: =MAX('HYD_Aggr'!D33:M33)<='HYD_Aggr'!C17+0.001
A29: HYD_Aggr: revenue = kWh x price (year 1) | B29: =ABS('HYD_Aggr'!D37-'HYD_Aggr'!D36*'HYD_Aggr'!C21)<1
A30: HYD_Aggr: EBITDA = gross profit - opex (year 5) | B30: =ABS('HYD_Aggr'!H48-('HYD_Aggr'!H39-'HYD_Aggr'!H47))<1
A31: HYD_Aggr: cumulative cash = sum of net cash flows | B31: =ABS('HYD_Aggr'!M58-SUM('HYD_Aggr'!C57:M57))<1
A32: HYD_Aggr: Excel NPV matches Python NPV (config A, all factors = 1) within Rs 1,000 | B32: =OR(Inputs!$C$4<>"A",ABS('HYD_Aggr'!C62-1488000.00)<1000)
A34: ALL CHECKS PASS | B34: =AND(B3:B32)

Sheet DEL_Cons
A1: Delhi - conservative scenario - station model (all formulas)
A2: Green = link to Inputs, black = calculation. Change inputs on the Inputs sheet only.
A4: Configuration | C4: =Inputs!$C$4
A5: 60 kW DC chargers | C5: =INDEX(Inputs!$C$63:$C$65,MATCH(C4,Inputs!$A$63:$A$65,0))
A6: 120 kW DC chargers | C6: =INDEX(Inputs!$D$63:$D$65,MATCH(C4,Inputs!$A$63:$A$65,0))
A7: 7.4 kW AC chargers | C7: =INDEX(Inputs!$E$63:$E$65,MATCH(C4,Inputs!$A$63:$A$65,0))
A8: Total chargers | C8: =C5+C6+C7
A9: Total connected kW | C9: =C5*60+C6*120+C7*7.4
A10: CAPEX multiplier (scenario x control) | C10: =Inputs!$C$36*Inputs!$C$8
A11: Chargers (Rs) | C11: =(C5*Inputs!$C$50+C6*Inputs!$C$51+C7*Inputs!$C$52)*C10
A12: Grid connection work (Rs) | C12: =INDEX(Inputs!$G$63:$G$65,MATCH(C4,Inputs!$A$63:$A$65,0))*100000*C10*Inputs!$C$9
A13: Civil & installation (Rs) | C13: =((C5+C6)*Inputs!$C$53+C7*Inputs!$C$54)*C10
A14: Signage, software set-up, permits (Rs) | C14: =Inputs!$C$55+Inputs!$C$56+Inputs!$C$57
A15: Contingency (Rs) | C15: =SUM(C11:C14)*Inputs!$C$37
A16: TOTAL CAPEX (Rs) | C16: =SUM(C11:C15)
A17: Capacity, kWh/day (at max practical utilisation) | C17: =C9*Inputs!$C$39*24*Inputs!$C$40*Inputs!$C$38
A18: Energy if in use 24h, kWh/day (for utilisation %) | C18: =C9*Inputs!$C$39*24
A19: Fair share of public demand, kWh/day | C19: =Inputs!$C$15/Inputs!$C$16
A20: Steady demand year 1, kWh/day | C20: =C19*Inputs!$C$17*Inputs!$C$5
A21: Price net of GST year 1 (Rs/kWh) | C21: =Inputs!$C$21*Inputs!$C$6
A22: Electricity tariff year 1 (Rs/kWh) | C22: =Inputs!$C$23*Inputs!$C$7
A23: Fixed electricity charge (Rs/month) | C23: =IF(AND(FALSE,C9>150),0,Inputs!$C$24)
A24: Host revenue share | C24: =IF(Inputs!$C$11="",Inputs!$C$27,Inputs!$C$11)
A25: Staff FTE | C25: =IF(Inputs!$C$10="",Inputs!$C$28,Inputs!$C$10)
A26: Discount rate (CAPM: Rf + beta x ERP) | C26: =IF(Inputs!$C$12="",Inputs!$C$44+Inputs!$C$46*Inputs!$C$45,Inputs!$C$12)
A27: Annual depreciation (Rs) | C27: =C16/Inputs!$C$42
A30: ANNUAL PROJECTION (Rs unless stated)
A31: Year | C31: 0 | D31: 1 | E31: 2 | F31: 3 | G31: 4 | H31: 5 | I31: 6 | J31: 7 | K31: 8 | L31: 9 | M31: 10
A32: Demand kWh/day | D32: =$C$20*(1+Inputs!$C$19)^(1-1)*Inputs!$C$18 | E32: =$C$20*(1+Inputs!$C$19)^(2-1) | F32: =$C$20*(1+Inputs!$C$19)^(3-1) | G32: =$C$20*(1+Inputs!$C$19)^(4-1) | H32: =$C$20*(1+Inputs!$C$19)^(5-1) | I32: =$C$20*(1+Inputs!$C$19)^(6-1) | J32: =$C$20*(1+Inputs!$C$19)^(7-1) | K32: =$C$20*(1+Inputs!$C$19)^(8-1) | L32: =$C$20*(1+Inputs!$C$19)^(9-1) | M32: =$C$20*(1+Inputs!$C$19)^(10-1)
A33: kWh sold per day | D33: =MIN(D32,$C$17) | E33: =MIN(E32,$C$17) | F33: =MIN(F32,$C$17) | G33: =MIN(G32,$C$17) | H33: =MIN(H32,$C$17) | I33: =MIN(I32,$C$17) | J33: =MIN(J32,$C$17) | K33: =MIN(K32,$C$17) | ... M33: =MIN(M32,$C$17)
A34: Sessions per day | D34: =D33/Inputs!$C$20 | E34: =E33/Inputs!$C$20 | F34: =F33/Inputs!$C$20 | G34: =G33/Inputs!$C$20 | H34: =H33/Inputs!$C$20 | I34: =I33/Inputs!$C$20 | J34: =J33/Inputs!$C$20 | K34: =K33/Inputs!$C$20 | ... M34: =M33/Inputs!$C$20
A35: Utilisation (% of hours) | D35: =D33/$C$18 | E35: =E33/$C$18 | F35: =F33/$C$18 | G35: =G33/$C$18 | H35: =H33/$C$18 | I35: =I33/$C$18 | J35: =J33/$C$18 | K35: =K33/$C$18 | ... M35: =M33/$C$18
A36: kWh sold per year | D36: =D33*365 | E36: =E33*365 | F36: =F33*365 | G36: =G33*365 | H36: =H33*365 | I36: =I33*365 | J36: =J33*365 | K36: =K33*365 | ... M36: =M33*365
A37: Revenue | D37: =D36*$C$21*(1+Inputs!$C$22)^(1-1) | E37: =E36*$C$21*(1+Inputs!$C$22)^(2-1) | F37: =F36*$C$21*(1+Inputs!$C$22)^(3-1) | G37: =G36*$C$21*(1+Inputs!$C$22)^(4-1) | H37: =H36*$C$21*(1+Inputs!$C$22)^(5-1) | I37: =I36*$C$21*(1+Inputs!$C$22)^(6-1) | J37: =J36*$C$21*(1+Inputs!$C$22)^(7-1) | K37: =K36*$C$21*(1+Inputs!$C$22)^(8-1) | L37: =L36*$C$21*(1+Inputs!$C$22)^(9-1) | M37: =M36*$C$21*(1+Inputs!$C$22)^(10-1)
A38: Electricity cost | D38: =(D36/(1-Inputs!$C$26)*$C$22+$C$23*12)*(1+Inputs!$C$25)^(1-1) | E38: =(E36/(1-Inputs!$C$26)*$C$22+$C$23*12)*(1+Inputs!$C$25)^(2-1) | F38: =(F36/(1-Inputs!$C$26)*$C$22+$C$23*12)*(1+Inputs!$C$25)^(3-1) | G38: =(G36/(1-Inputs!$C$26)*$C$22+$C$23*12)*(1+Inputs!$C$25)^(4-1) | H38: =(H36/(1-Inputs!$C$26)*$C$22+$C$23*12)*(1+Inputs!$C$25)^(5-1) | I38: =(I36/(1-Inputs!$C$26)*$C$22+$C$23*12)*(1+Inputs!$C$25)^(6-1) | J38: =(J36/(1-Inputs!$C$26)*$C$22+$C$23*12)*(1+Inputs!$C$25)^(7-1) | K38: =(K36/(1-Inputs!$C$26)*$C$22+$C$23*12)*(1+Inputs!$C$25)^(8-1) | L38: =(L36/(1-Inputs!$C$26)*$C$22+$C$23*12)*(1+Inputs!$C$25)^(9-1) | M38: =(M36/(1-Inputs!$C$26)*$C$22+$C$23*12)*(1+Inputs!$C$25)^(10-1)
A39: Gross profit | D39: =D37-D38 | E39: =E37-E38 | F39: =F37-F38 | G39: =G37-G38 | H39: =H37-H38 | I39: =I37-I38 | J39: =J37-J38 | K39: =K37-K38 | ... M39: =M37-M38
A40: Host revenue share | D40: =D37*$C$24 | E40: =E37*$C$24 | F40: =F37*$C$24 | G40: =G37*$C$24 | H40: =H37*$C$24 | I40: =I37*$C$24 | J40: =J37*$C$24 | K40: =K37*$C$24 | ... M40: =M37*$C$24
A41: Staff | D41: =$C$25*Inputs!$C$29*12*(1+Inputs!$C$35)^(1-1) | E41: =$C$25*Inputs!$C$29*12*(1+Inputs!$C$35)^(2-1) | F41: =$C$25*Inputs!$C$29*12*(1+Inputs!$C$35)^(3-1) | G41: =$C$25*Inputs!$C$29*12*(1+Inputs!$C$35)^(4-1) | H41: =$C$25*Inputs!$C$29*12*(1+Inputs!$C$35)^(5-1) | I41: =$C$25*Inputs!$C$29*12*(1+Inputs!$C$35)^(6-1) | J41: =$C$25*Inputs!$C$29*12*(1+Inputs!$C$35)^(7-1) | K41: =$C$25*Inputs!$C$29*12*(1+Inputs!$C$35)^(8-1) | L41: =$C$25*Inputs!$C$29*12*(1+Inputs!$C$35)^(9-1) | M41: =$C$25*Inputs!$C$29*12*(1+Inputs!$C$35)^(10-1)
A42: Maintenance | D42: =$C$11*Inputs!$C$30*(1+Inputs!$C$35)^(1-1) | E42: =$C$11*Inputs!$C$30*(1+Inputs!$C$35)^(2-1) | F42: =$C$11*Inputs!$C$30*(1+Inputs!$C$35)^(3-1) | G42: =$C$11*Inputs!$C$30*(1+Inputs!$C$35)^(4-1) | H42: =$C$11*Inputs!$C$30*(1+Inputs!$C$35)^(5-1) | I42: =$C$11*Inputs!$C$30*(1+Inputs!$C$35)^(6-1) | J42: =$C$11*Inputs!$C$30*(1+Inputs!$C$35)^(7-1) | K42: =$C$11*Inputs!$C$30*(1+Inputs!$C$35)^(8-1) | L42: =$C$11*Inputs!$C$30*(1+Inputs!$C$35)^(9-1) | M42: =$C$11*Inputs!$C$30*(1+Inputs!$C$35)^(10-1)
A43: Software / CMS | D43: =$C$8*Inputs!$C$31*12*(1+Inputs!$C$35)^(1-1) | E43: =$C$8*Inputs!$C$31*12*(1+Inputs!$C$35)^(2-1) | F43: =$C$8*Inputs!$C$31*12*(1+Inputs!$C$35)^(3-1) | G43: =$C$8*Inputs!$C$31*12*(1+Inputs!$C$35)^(4-1) | H43: =$C$8*Inputs!$C$31*12*(1+Inputs!$C$35)^(5-1) | I43: =$C$8*Inputs!$C$31*12*(1+Inputs!$C$35)^(6-1) | J43: =$C$8*Inputs!$C$31*12*(1+Inputs!$C$35)^(7-1) | K43: =$C$8*Inputs!$C$31*12*(1+Inputs!$C$35)^(8-1) | L43: =$C$8*Inputs!$C$31*12*(1+Inputs!$C$35)^(9-1) | M43: =$C$8*Inputs!$C$31*12*(1+Inputs!$C$35)^(10-1)
...

Sheet DEL_Base
A1: Delhi - base scenario - station model (all formulas)
A2: Green = link to Inputs, black = calculation. Change inputs on the Inputs sheet only.
A4: Configuration | C4: =Inputs!$C$4
A5: 60 kW DC chargers | C5: =INDEX(Inputs!$C$63:$C$65,MATCH(C4,Inputs!$A$63:$A$65,0))
A6: 120 kW DC chargers | C6: =INDEX(Inputs!$D$63:$D$65,MATCH(C4,Inputs!$A$63:$A$65,0))
A7: 7.4 kW AC chargers | C7: =INDEX(Inputs!$E$63:$E$65,MATCH(C4,Inputs!$A$63:$A$65,0))
A8: Total chargers | C8: =C5+C6+C7
A9: Total connected kW | C9: =C5*60+C6*120+C7*7.4
A10: CAPEX multiplier (scenario x control) | C10: =Inputs!$D$36*Inputs!$C$8
A11: Chargers (Rs) | C11: =(C5*Inputs!$C$50+C6*Inputs!$C$51+C7*Inputs!$C$52)*C10
A12: Grid connection work (Rs) | C12: =INDEX(Inputs!$G$63:$G$65,MATCH(C4,Inputs!$A$63:$A$65,0))*100000*C10*Inputs!$C$9
A13: Civil & installation (Rs) | C13: =((C5+C6)*Inputs!$C$53+C7*Inputs!$C$54)*C10
A14: Signage, software set-up, permits (Rs) | C14: =Inputs!$C$55+Inputs!$C$56+Inputs!$C$57
A15: Contingency (Rs) | C15: =SUM(C11:C14)*Inputs!$D$37
A16: TOTAL CAPEX (Rs) | C16: =SUM(C11:C15)
A17: Capacity, kWh/day (at max practical utilisation) | C17: =C9*Inputs!$D$39*24*Inputs!$D$40*Inputs!$D$38
A18: Energy if in use 24h, kWh/day (for utilisation %) | C18: =C9*Inputs!$D$39*24
A19: Fair share of public demand, kWh/day | C19: =Inputs!$D$15/Inputs!$D$16
A20: Steady demand year 1, kWh/day | C20: =C19*Inputs!$D$17*Inputs!$C$5
A21: Price net of GST year 1 (Rs/kWh) | C21: =Inputs!$D$21*Inputs!$C$6
A22: Electricity tariff year 1 (Rs/kWh) | C22: =Inputs!$D$23*Inputs!$C$7
A23: Fixed electricity charge (Rs/month) | C23: =IF(AND(FALSE,C9>150),0,Inputs!$D$24)
A24: Host revenue share | C24: =IF(Inputs!$C$11="",Inputs!$D$27,Inputs!$C$11)
A25: Staff FTE | C25: =IF(Inputs!$C$10="",Inputs!$D$28,Inputs!$C$10)
A26: Discount rate (CAPM: Rf + beta x ERP) | C26: =IF(Inputs!$C$12="",Inputs!$D$44+Inputs!$D$46*Inputs!$D$45,Inputs!$C$12)
A27: Annual depreciation (Rs) | C27: =C16/Inputs!$D$42
A30: ANNUAL PROJECTION (Rs unless stated)
A31: Year | C31: 0 | D31: 1 | E31: 2 | F31: 3 | G31: 4 | H31: 5 | I31: 6 | J31: 7 | K31: 8 | L31: 9 | M31: 10
A32: Demand kWh/day | D32: =$C$20*(1+Inputs!$D$19)^(1-1)*Inputs!$D$18 | E32: =$C$20*(1+Inputs!$D$19)^(2-1) | F32: =$C$20*(1+Inputs!$D$19)^(3-1) | G32: =$C$20*(1+Inputs!$D$19)^(4-1) | H32: =$C$20*(1+Inputs!$D$19)^(5-1) | I32: =$C$20*(1+Inputs!$D$19)^(6-1) | J32: =$C$20*(1+Inputs!$D$19)^(7-1) | K32: =$C$20*(1+Inputs!$D$19)^(8-1) | L32: =$C$20*(1+Inputs!$D$19)^(9-1) | M32: =$C$20*(1+Inputs!$D$19)^(10-1)
A33: kWh sold per day | D33: =MIN(D32,$C$17) | E33: =MIN(E32,$C$17) | F33: =MIN(F32,$C$17) | G33: =MIN(G32,$C$17) | H33: =MIN(H32,$C$17) | I33: =MIN(I32,$C$17) | J33: =MIN(J32,$C$17) | K33: =MIN(K32,$C$17) | ... M33: =MIN(M32,$C$17)
A34: Sessions per day | D34: =D33/Inputs!$D$20 | E34: =E33/Inputs!$D$20 | F34: =F33/Inputs!$D$20 | G34: =G33/Inputs!$D$20 | H34: =H33/Inputs!$D$20 | I34: =I33/Inputs!$D$20 | J34: =J33/Inputs!$D$20 | K34: =K33/Inputs!$D$20 | ... M34: =M33/Inputs!$D$20
A35: Utilisation (% of hours) | D35: =D33/$C$18 | E35: =E33/$C$18 | F35: =F33/$C$18 | G35: =G33/$C$18 | H35: =H33/$C$18 | I35: =I33/$C$18 | J35: =J33/$C$18 | K35: =K33/$C$18 | ... M35: =M33/$C$18
A36: kWh sold per year | D36: =D33*365 | E36: =E33*365 | F36: =F33*365 | G36: =G33*365 | H36: =H33*365 | I36: =I33*365 | J36: =J33*365 | K36: =K33*365 | ... M36: =M33*365
A37: Revenue | D37: =D36*$C$21*(1+Inputs!$D$22)^(1-1) | E37: =E36*$C$21*(1+Inputs!$D$22)^(2-1) | F37: =F36*$C$21*(1+Inputs!$D$22)^(3-1) | G37: =G36*$C$21*(1+Inputs!$D$22)^(4-1) | H37: =H36*$C$21*(1+Inputs!$D$22)^(5-1) | I37: =I36*$C$21*(1+Inputs!$D$22)^(6-1) | J37: =J36*$C$21*(1+Inputs!$D$22)^(7-1) | K37: =K36*$C$21*(1+Inputs!$D$22)^(8-1) | L37: =L36*$C$21*(1+Inputs!$D$22)^(9-1) | M37: =M36*$C$21*(1+Inputs!$D$22)^(10-1)
A38: Electricity cost | D38: =(D36/(1-Inputs!$D$26)*$C$22+$C$23*12)*(1+Inputs!$D$25)^(1-1) | E38: =(E36/(1-Inputs!$D$26)*$C$22+$C$23*12)*(1+Inputs!$D$25)^(2-1) | F38: =(F36/(1-Inputs!$D$26)*$C$22+$C$23*12)*(1+Inputs!$D$25)^(3-1) | G38: =(G36/(1-Inputs!$D$26)*$C$22+$C$23*12)*(1+Inputs!$D$25)^(4-1) | H38: =(H36/(1-Inputs!$D$26)*$C$22+$C$23*12)*(1+Inputs!$D$25)^(5-1) | I38: =(I36/(1-Inputs!$D$26)*$C$22+$C$23*12)*(1+Inputs!$D$25)^(6-1) | J38: =(J36/(1-Inputs!$D$26)*$C$22+$C$23*12)*(1+Inputs!$D$25)^(7-1) | K38: =(K36/(1-Inputs!$D$26)*$C$22+$C$23*12)*(1+Inputs!$D$25)^(8-1) | L38: =(L36/(1-Inputs!$D$26)*$C$22+$C$23*12)*(1+Inputs!$D$25)^(9-1) | M38: =(M36/(1-Inputs!$D$26)*$C$22+$C$23*12)*(1+Inputs!$D$25)^(10-1)
A39: Gross profit | D39: =D37-D38 | E39: =E37-E38 | F39: =F37-F38 | G39: =G37-G38 | H39: =H37-H38 | I39: =I37-I38 | J39: =J37-J38 | K39: =K37-K38 | ... M39: =M37-M38
A40: Host revenue share | D40: =D37*$C$24 | E40: =E37*$C$24 | F40: =F37*$C$24 | G40: =G37*$C$24 | H40: =H37*$C$24 | I40: =I37*$C$24 | J40: =J37*$C$24 | K40: =K37*$C$24 | ... M40: =M37*$C$24
A41: Staff | D41: =$C$25*Inputs!$D$29*12*(1+Inputs!$D$35)^(1-1) | E41: =$C$25*Inputs!$D$29*12*(1+Inputs!$D$35)^(2-1) | F41: =$C$25*Inputs!$D$29*12*(1+Inputs!$D$35)^(3-1) | G41: =$C$25*Inputs!$D$29*12*(1+Inputs!$D$35)^(4-1) | H41: =$C$25*Inputs!$D$29*12*(1+Inputs!$D$35)^(5-1) | I41: =$C$25*Inputs!$D$29*12*(1+Inputs!$D$35)^(6-1) | J41: =$C$25*Inputs!$D$29*12*(1+Inputs!$D$35)^(7-1) | K41: =$C$25*Inputs!$D$29*12*(1+Inputs!$D$35)^(8-1) | L41: =$C$25*Inputs!$D$29*12*(1+Inputs!$D$35)^(9-1) | M41: =$C$25*Inputs!$D$29*12*(1+Inputs!$D$35)^(10-1)
A42: Maintenance | D42: =$C$11*Inputs!$D$30*(1+Inputs!$D$35)^(1-1) | E42: =$C$11*Inputs!$D$30*(1+Inputs!$D$35)^(2-1) | F42: =$C$11*Inputs!$D$30*(1+Inputs!$D$35)^(3-1) | G42: =$C$11*Inputs!$D$30*(1+Inputs!$D$35)^(4-1) | H42: =$C$11*Inputs!$D$30*(1+Inputs!$D$35)^(5-1) | I42: =$C$11*Inputs!$D$30*(1+Inputs!$D$35)^(6-1) | J42: =$C$11*Inputs!$D$30*(1+Inputs!$D$35)^(7-1) | K42: =$C$11*Inputs!$D$30*(1+Inputs!$D$35)^(8-1) | L42: =$C$11*Inputs!$D$30*(1+Inputs!$D$35)^(9-1) | M42: =$C$11*Inputs!$D$30*(1+Inputs!$D$35)^(10-1)
A43: Software / CMS | D43: =$C$8*Inputs!$D$31*12*(1+Inputs!$D$35)^(1-1) | E43: =$C$8*Inputs!$D$31*12*(1+Inputs!$D$35)^(2-1) | F43: =$C$8*Inputs!$D$31*12*(1+Inputs!$D$35)^(3-1) | G43: =$C$8*Inputs!$D$31*12*(1+Inputs!$D$35)^(4-1) | H43: =$C$8*Inputs!$D$31*12*(1+Inputs!$D$35)^(5-1) | I43: =$C$8*Inputs!$D$31*12*(1+Inputs!$D$35)^(6-1) | J43: =$C$8*Inputs!$D$31*12*(1+Inputs!$D$35)^(7-1) | K43: =$C$8*Inputs!$D$31*12*(1+Inputs!$D$35)^(8-1) | L43: =$C$8*Inputs!$D$31*12*(1+Inputs!$D$35)^(9-1) | M43: =$C$8*Inputs!$D$31*12*(1+Inputs!$D$35)^(10-1)
...

Sheet DEL_Aggr
A1: Delhi - aggressive scenario - station model (all formulas)
A2: Green = link to Inputs, black = calculation. Change inputs on the Inputs sheet only.
A4: Configuration | C4: =Inputs!$C$4
A5: 60 kW DC chargers | C5: =INDEX(Inputs!$C$63:$C$65,MATCH(C4,Inputs!$A$63:$A$65,0))
A6: 120 kW DC chargers | C6: =INDEX(Inputs!$D$63:$D$65,MATCH(C4,Inputs!$A$63:$A$65,0))
A7: 7.4 kW AC chargers | C7: =INDEX(Inputs!$E$63:$E$65,MATCH(C4,Inputs!$A$63:$A$65,0))
A8: Total chargers | C8: =C5+C6+C7
A9: Total connected kW | C9: =C5*60+C6*120+C7*7.4
A10: CAPEX multiplier (scenario x control) | C10: =Inputs!$E$36*Inputs!$C$8
A11: Chargers (Rs) | C11: =(C5*Inputs!$C$50+C6*Inputs!$C$51+C7*Inputs!$C$52)*C10
A12: Grid connection work (Rs) | C12: =INDEX(Inputs!$G$63:$G$65,MATCH(C4,Inputs!$A$63:$A$65,0))*100000*C10*Inputs!$C$9
A13: Civil & installation (Rs) | C13: =((C5+C6)*Inputs!$C$53+C7*Inputs!$C$54)*C10
A14: Signage, software set-up, permits (Rs) | C14: =Inputs!$C$55+Inputs!$C$56+Inputs!$C$57
A15: Contingency (Rs) | C15: =SUM(C11:C14)*Inputs!$E$37
A16: TOTAL CAPEX (Rs) | C16: =SUM(C11:C15)
A17: Capacity, kWh/day (at max practical utilisation) | C17: =C9*Inputs!$E$39*24*Inputs!$E$40*Inputs!$E$38
A18: Energy if in use 24h, kWh/day (for utilisation %) | C18: =C9*Inputs!$E$39*24
A19: Fair share of public demand, kWh/day | C19: =Inputs!$E$15/Inputs!$E$16
A20: Steady demand year 1, kWh/day | C20: =C19*Inputs!$E$17*Inputs!$C$5
A21: Price net of GST year 1 (Rs/kWh) | C21: =Inputs!$E$21*Inputs!$C$6
A22: Electricity tariff year 1 (Rs/kWh) | C22: =Inputs!$E$23*Inputs!$C$7
A23: Fixed electricity charge (Rs/month) | C23: =IF(AND(FALSE,C9>150),0,Inputs!$E$24)
A24: Host revenue share | C24: =IF(Inputs!$C$11="",Inputs!$E$27,Inputs!$C$11)
A25: Staff FTE | C25: =IF(Inputs!$C$10="",Inputs!$E$28,Inputs!$C$10)
A26: Discount rate (CAPM: Rf + beta x ERP) | C26: =IF(Inputs!$C$12="",Inputs!$E$44+Inputs!$E$46*Inputs!$E$45,Inputs!$C$12)
A27: Annual depreciation (Rs) | C27: =C16/Inputs!$E$42
A30: ANNUAL PROJECTION (Rs unless stated)
A31: Year | C31: 0 | D31: 1 | E31: 2 | F31: 3 | G31: 4 | H31: 5 | I31: 6 | J31: 7 | K31: 8 | L31: 9 | M31: 10
A32: Demand kWh/day | D32: =$C$20*(1+Inputs!$E$19)^(1-1)*Inputs!$E$18 | E32: =$C$20*(1+Inputs!$E$19)^(2-1) | F32: =$C$20*(1+Inputs!$E$19)^(3-1) | G32: =$C$20*(1+Inputs!$E$19)^(4-1) | H32: =$C$20*(1+Inputs!$E$19)^(5-1) | I32: =$C$20*(1+Inputs!$E$19)^(6-1) | J32: =$C$20*(1+Inputs!$E$19)^(7-1) | K32: =$C$20*(1+Inputs!$E$19)^(8-1) | L32: =$C$20*(1+Inputs!$E$19)^(9-1) | M32: =$C$20*(1+Inputs!$E$19)^(10-1)
A33: kWh sold per day | D33: =MIN(D32,$C$17) | E33: =MIN(E32,$C$17) | F33: =MIN(F32,$C$17) | G33: =MIN(G32,$C$17) | H33: =MIN(H32,$C$17) | I33: =MIN(I32,$C$17) | J33: =MIN(J32,$C$17) | K33: =MIN(K32,$C$17) | ... M33: =MIN(M32,$C$17)
A34: Sessions per day | D34: =D33/Inputs!$E$20 | E34: =E33/Inputs!$E$20 | F34: =F33/Inputs!$E$20 | G34: =G33/Inputs!$E$20 | H34: =H33/Inputs!$E$20 | I34: =I33/Inputs!$E$20 | J34: =J33/Inputs!$E$20 | K34: =K33/Inputs!$E$20 | ... M34: =M33/Inputs!$E$20
A35: Utilisation (% of hours) | D35: =D33/$C$18 | E35: =E33/$C$18 | F35: =F33/$C$18 | G35: =G33/$C$18 | H35: =H33/$C$18 | I35: =I33/$C$18 | J35: =J33/$C$18 | K35: =K33/$C$18 | ... M35: =M33/$C$18
A36: kWh sold per year | D36: =D33*365 | E36: =E33*365 | F36: =F33*365 | G36: =G33*365 | H36: =H33*365 | I36: =I33*365 | J36: =J33*365 | K36: =K33*365 | ... M36: =M33*365
A37: Revenue | D37: =D36*$C$21*(1+Inputs!$E$22)^(1-1) | E37: =E36*$C$21*(1+Inputs!$E$22)^(2-1) | F37: =F36*$C$21*(1+Inputs!$E$22)^(3-1) | G37: =G36*$C$21*(1+Inputs!$E$22)^(4-1) | H37: =H36*$C$21*(1+Inputs!$E$22)^(5-1) | I37: =I36*$C$21*(1+Inputs!$E$22)^(6-1) | J37: =J36*$C$21*(1+Inputs!$E$22)^(7-1) | K37: =K36*$C$21*(1+Inputs!$E$22)^(8-1) | L37: =L36*$C$21*(1+Inputs!$E$22)^(9-1) | M37: =M36*$C$21*(1+Inputs!$E$22)^(10-1)
A38: Electricity cost | D38: =(D36/(1-Inputs!$E$26)*$C$22+$C$23*12)*(1+Inputs!$E$25)^(1-1) | E38: =(E36/(1-Inputs!$E$26)*$C$22+$C$23*12)*(1+Inputs!$E$25)^(2-1) | F38: =(F36/(1-Inputs!$E$26)*$C$22+$C$23*12)*(1+Inputs!$E$25)^(3-1) | G38: =(G36/(1-Inputs!$E$26)*$C$22+$C$23*12)*(1+Inputs!$E$25)^(4-1) | H38: =(H36/(1-Inputs!$E$26)*$C$22+$C$23*12)*(1+Inputs!$E$25)^(5-1) | I38: =(I36/(1-Inputs!$E$26)*$C$22+$C$23*12)*(1+Inputs!$E$25)^(6-1) | J38: =(J36/(1-Inputs!$E$26)*$C$22+$C$23*12)*(1+Inputs!$E$25)^(7-1) | K38: =(K36/(1-Inputs!$E$26)*$C$22+$C$23*12)*(1+Inputs!$E$25)^(8-1) | L38: =(L36/(1-Inputs!$E$26)*$C$22+$C$23*12)*(1+Inputs!$E$25)^(9-1) | M38: =(M36/(1-Inputs!$E$26)*$C$22+$C$23*12)*(1+Inputs!$E$25)^(10-1)
A39: Gross profit | D39: =D37-D38 | E39: =E37-E38 | F39: =F37-F38 | G39: =G37-G38 | H39: =H37-H38 | I39: =I37-I38 | J39: =J37-J38 | K39: =K37-K38 | ... M39: =M37-M38
A40: Host revenue share | D40: =D37*$C$24 | E40: =E37*$C$24 | F40: =F37*$C$24 | G40: =G37*$C$24 | H40: =H37*$C$24 | I40: =I37*$C$24 | J40: =J37*$C$24 | K40: =K37*$C$24 | ... M40: =M37*$C$24
A41: Staff | D41: =$C$25*Inputs!$E$29*12*(1+Inputs!$E$35)^(1-1) | E41: =$C$25*Inputs!$E$29*12*(1+Inputs!$E$35)^(2-1) | F41: =$C$25*Inputs!$E$29*12*(1+Inputs!$E$35)^(3-1) | G41: =$C$25*Inputs!$E$29*12*(1+Inputs!$E$35)^(4-1) | H41: =$C$25*Inputs!$E$29*12*(1+Inputs!$E$35)^(5-1) | I41: =$C$25*Inputs!$E$29*12*(1+Inputs!$E$35)^(6-1) | J41: =$C$25*Inputs!$E$29*12*(1+Inputs!$E$35)^(7-1) | K41: =$C$25*Inputs!$E$29*12*(1+Inputs!$E$35)^(8-1) | L41: =$C$25*Inputs!$E$29*12*(1+Inputs!$E$35)^(9-1) | M41: =$C$25*Inputs!$E$29*12*(1+Inputs!$E$35)^(10-1)
A42: Maintenance | D42: =$C$11*Inputs!$E$30*(1+Inputs!$E$35)^(1-1) | E42: =$C$11*Inputs!$E$30*(1+Inputs!$E$35)^(2-1) | F42: =$C$11*Inputs!$E$30*(1+Inputs!$E$35)^(3-1) | G42: =$C$11*Inputs!$E$30*(1+Inputs!$E$35)^(4-1) | H42: =$C$11*Inputs!$E$30*(1+Inputs!$E$35)^(5-1) | I42: =$C$11*Inputs!$E$30*(1+Inputs!$E$35)^(6-1) | J42: =$C$11*Inputs!$E$30*(1+Inputs!$E$35)^(7-1) | K42: =$C$11*Inputs!$E$30*(1+Inputs!$E$35)^(8-1) | L42: =$C$11*Inputs!$E$30*(1+Inputs!$E$35)^(9-1) | M42: =$C$11*Inputs!$E$30*(1+Inputs!$E$35)^(10-1)
A43: Software / CMS | D43: =$C$8*Inputs!$E$31*12*(1+Inputs!$E$35)^(1-1) | E43: =$C$8*Inputs!$E$31*12*(1+Inputs!$E$35)^(2-1) | F43: =$C$8*Inputs!$E$31*12*(1+Inputs!$E$35)^(3-1) | G43: =$C$8*Inputs!$E$31*12*(1+Inputs!$E$35)^(4-1) | H43: =$C$8*Inputs!$E$31*12*(1+Inputs!$E$35)^(5-1) | I43: =$C$8*Inputs!$E$31*12*(1+Inputs!$E$35)^(6-1) | J43: =$C$8*Inputs!$E$31*12*(1+Inputs!$E$35)^(7-1) | K43: =$C$8*Inputs!$E$31*12*(1+Inputs!$E$35)^(8-1) | L43: =$C$8*Inputs!$E$31*12*(1+Inputs!$E$35)^(9-1) | M43: =$C$8*Inputs!$E$31*12*(1+Inputs!$E$35)^(10-1)
...

Sheet HYD_Cons
A1: Hyderabad - conservative scenario - station model (all formulas)
A2: Green = link to Inputs, black = calculation. Change inputs on the Inputs sheet only.
A4: Configuration | C4: =Inputs!$C$4
A5: 60 kW DC chargers | C5: =INDEX(Inputs!$C$63:$C$65,MATCH(C4,Inputs!$A$63:$A$65,0))
A6: 120 kW DC chargers | C6: =INDEX(Inputs!$D$63:$D$65,MATCH(C4,Inputs!$A$63:$A$65,0))
A7: 7.4 kW AC chargers | C7: =INDEX(Inputs!$E$63:$E$65,MATCH(C4,Inputs!$A$63:$A$65,0))
A8: Total chargers | C8: =C5+C6+C7
A9: Total connected kW | C9: =C5*60+C6*120+C7*7.4
A10: CAPEX multiplier (scenario x control) | C10: =Inputs!$F$36*Inputs!$C$8
A11: Chargers (Rs) | C11: =(C5*Inputs!$C$50+C6*Inputs!$C$51+C7*Inputs!$C$52)*C10
A12: Grid connection work (Rs) | C12: =INDEX(Inputs!$G$63:$G$65,MATCH(C4,Inputs!$A$63:$A$65,0))*100000*C10*Inputs!$C$9
A13: Civil & installation (Rs) | C13: =((C5+C6)*Inputs!$C$53+C7*Inputs!$C$54)*C10
A14: Signage, software set-up, permits (Rs) | C14: =Inputs!$C$55+Inputs!$C$56+Inputs!$C$57
A15: Contingency (Rs) | C15: =SUM(C11:C14)*Inputs!$F$37
A16: TOTAL CAPEX (Rs) | C16: =SUM(C11:C15)
A17: Capacity, kWh/day (at max practical utilisation) | C17: =C9*Inputs!$F$39*24*Inputs!$F$40*Inputs!$F$38
A18: Energy if in use 24h, kWh/day (for utilisation %) | C18: =C9*Inputs!$F$39*24
A19: Fair share of public demand, kWh/day | C19: =Inputs!$F$15/Inputs!$F$16
A20: Steady demand year 1, kWh/day | C20: =C19*Inputs!$F$17*Inputs!$C$5
A21: Price net of GST year 1 (Rs/kWh) | C21: =Inputs!$F$21*Inputs!$C$6
A22: Electricity tariff year 1 (Rs/kWh) | C22: =Inputs!$F$23*Inputs!$C$7
A23: Fixed electricity charge (Rs/month) | C23: =IF(AND(TRUE,C9>150),C9/0.95*Inputs!$C$58+Inputs!$C$59,Inputs!$F$24)
A24: Host revenue share | C24: =IF(Inputs!$C$11="",Inputs!$F$27,Inputs!$C$11)
A25: Staff FTE | C25: =IF(Inputs!$C$10="",Inputs!$F$28,Inputs!$C$10)
A26: Discount rate (CAPM: Rf + beta x ERP) | C26: =IF(Inputs!$C$12="",Inputs!$F$44+Inputs!$F$46*Inputs!$F$45,Inputs!$C$12)
A27: Annual depreciation (Rs) | C27: =C16/Inputs!$F$42
A30: ANNUAL PROJECTION (Rs unless stated)
A31: Year | C31: 0 | D31: 1 | E31: 2 | F31: 3 | G31: 4 | H31: 5 | I31: 6 | J31: 7 | K31: 8 | L31: 9 | M31: 10
A32: Demand kWh/day | D32: =$C$20*(1+Inputs!$F$19)^(1-1)*Inputs!$F$18 | E32: =$C$20*(1+Inputs!$F$19)^(2-1) | F32: =$C$20*(1+Inputs!$F$19)^(3-1) | G32: =$C$20*(1+Inputs!$F$19)^(4-1) | H32: =$C$20*(1+Inputs!$F$19)^(5-1) | I32: =$C$20*(1+Inputs!$F$19)^(6-1) | J32: =$C$20*(1+Inputs!$F$19)^(7-1) | K32: =$C$20*(1+Inputs!$F$19)^(8-1) | L32: =$C$20*(1+Inputs!$F$19)^(9-1) | M32: =$C$20*(1+Inputs!$F$19)^(10-1)
A33: kWh sold per day | D33: =MIN(D32,$C$17) | E33: =MIN(E32,$C$17) | F33: =MIN(F32,$C$17) | G33: =MIN(G32,$C$17) | H33: =MIN(H32,$C$17) | I33: =MIN(I32,$C$17) | J33: =MIN(J32,$C$17) | K33: =MIN(K32,$C$17) | ... M33: =MIN(M32,$C$17)
A34: Sessions per day | D34: =D33/Inputs!$F$20 | E34: =E33/Inputs!$F$20 | F34: =F33/Inputs!$F$20 | G34: =G33/Inputs!$F$20 | H34: =H33/Inputs!$F$20 | I34: =I33/Inputs!$F$20 | J34: =J33/Inputs!$F$20 | K34: =K33/Inputs!$F$20 | ... M34: =M33/Inputs!$F$20
A35: Utilisation (% of hours) | D35: =D33/$C$18 | E35: =E33/$C$18 | F35: =F33/$C$18 | G35: =G33/$C$18 | H35: =H33/$C$18 | I35: =I33/$C$18 | J35: =J33/$C$18 | K35: =K33/$C$18 | ... M35: =M33/$C$18
A36: kWh sold per year | D36: =D33*365 | E36: =E33*365 | F36: =F33*365 | G36: =G33*365 | H36: =H33*365 | I36: =I33*365 | J36: =J33*365 | K36: =K33*365 | ... M36: =M33*365
A37: Revenue | D37: =D36*$C$21*(1+Inputs!$F$22)^(1-1) | E37: =E36*$C$21*(1+Inputs!$F$22)^(2-1) | F37: =F36*$C$21*(1+Inputs!$F$22)^(3-1) | G37: =G36*$C$21*(1+Inputs!$F$22)^(4-1) | H37: =H36*$C$21*(1+Inputs!$F$22)^(5-1) | I37: =I36*$C$21*(1+Inputs!$F$22)^(6-1) | J37: =J36*$C$21*(1+Inputs!$F$22)^(7-1) | K37: =K36*$C$21*(1+Inputs!$F$22)^(8-1) | L37: =L36*$C$21*(1+Inputs!$F$22)^(9-1) | M37: =M36*$C$21*(1+Inputs!$F$22)^(10-1)
A38: Electricity cost | D38: =(D36/(1-Inputs!$F$26)*$C$22+$C$23*12)*(1+Inputs!$F$25)^(1-1) | E38: =(E36/(1-Inputs!$F$26)*$C$22+$C$23*12)*(1+Inputs!$F$25)^(2-1) | F38: =(F36/(1-Inputs!$F$26)*$C$22+$C$23*12)*(1+Inputs!$F$25)^(3-1) | G38: =(G36/(1-Inputs!$F$26)*$C$22+$C$23*12)*(1+Inputs!$F$25)^(4-1) | H38: =(H36/(1-Inputs!$F$26)*$C$22+$C$23*12)*(1+Inputs!$F$25)^(5-1) | I38: =(I36/(1-Inputs!$F$26)*$C$22+$C$23*12)*(1+Inputs!$F$25)^(6-1) | J38: =(J36/(1-Inputs!$F$26)*$C$22+$C$23*12)*(1+Inputs!$F$25)^(7-1) | K38: =(K36/(1-Inputs!$F$26)*$C$22+$C$23*12)*(1+Inputs!$F$25)^(8-1) | L38: =(L36/(1-Inputs!$F$26)*$C$22+$C$23*12)*(1+Inputs!$F$25)^(9-1) | M38: =(M36/(1-Inputs!$F$26)*$C$22+$C$23*12)*(1+Inputs!$F$25)^(10-1)
A39: Gross profit | D39: =D37-D38 | E39: =E37-E38 | F39: =F37-F38 | G39: =G37-G38 | H39: =H37-H38 | I39: =I37-I38 | J39: =J37-J38 | K39: =K37-K38 | ... M39: =M37-M38
A40: Host revenue share | D40: =D37*$C$24 | E40: =E37*$C$24 | F40: =F37*$C$24 | G40: =G37*$C$24 | H40: =H37*$C$24 | I40: =I37*$C$24 | J40: =J37*$C$24 | K40: =K37*$C$24 | ... M40: =M37*$C$24
A41: Staff | D41: =$C$25*Inputs!$F$29*12*(1+Inputs!$F$35)^(1-1) | E41: =$C$25*Inputs!$F$29*12*(1+Inputs!$F$35)^(2-1) | F41: =$C$25*Inputs!$F$29*12*(1+Inputs!$F$35)^(3-1) | G41: =$C$25*Inputs!$F$29*12*(1+Inputs!$F$35)^(4-1) | H41: =$C$25*Inputs!$F$29*12*(1+Inputs!$F$35)^(5-1) | I41: =$C$25*Inputs!$F$29*12*(1+Inputs!$F$35)^(6-1) | J41: =$C$25*Inputs!$F$29*12*(1+Inputs!$F$35)^(7-1) | K41: =$C$25*Inputs!$F$29*12*(1+Inputs!$F$35)^(8-1) | L41: =$C$25*Inputs!$F$29*12*(1+Inputs!$F$35)^(9-1) | M41: =$C$25*Inputs!$F$29*12*(1+Inputs!$F$35)^(10-1)
A42: Maintenance | D42: =$C$11*Inputs!$F$30*(1+Inputs!$F$35)^(1-1) | E42: =$C$11*Inputs!$F$30*(1+Inputs!$F$35)^(2-1) | F42: =$C$11*Inputs!$F$30*(1+Inputs!$F$35)^(3-1) | G42: =$C$11*Inputs!$F$30*(1+Inputs!$F$35)^(4-1) | H42: =$C$11*Inputs!$F$30*(1+Inputs!$F$35)^(5-1) | I42: =$C$11*Inputs!$F$30*(1+Inputs!$F$35)^(6-1) | J42: =$C$11*Inputs!$F$30*(1+Inputs!$F$35)^(7-1) | K42: =$C$11*Inputs!$F$30*(1+Inputs!$F$35)^(8-1) | L42: =$C$11*Inputs!$F$30*(1+Inputs!$F$35)^(9-1) | M42: =$C$11*Inputs!$F$30*(1+Inputs!$F$35)^(10-1)
A43: Software / CMS | D43: =$C$8*Inputs!$F$31*12*(1+Inputs!$F$35)^(1-1) | E43: =$C$8*Inputs!$F$31*12*(1+Inputs!$F$35)^(2-1) | F43: =$C$8*Inputs!$F$31*12*(1+Inputs!$F$35)^(3-1) | G43: =$C$8*Inputs!$F$31*12*(1+Inputs!$F$35)^(4-1) | H43: =$C$8*Inputs!$F$31*12*(1+Inputs!$F$35)^(5-1) | I43: =$C$8*Inputs!$F$31*12*(1+Inputs!$F$35)^(6-1) | J43: =$C$8*Inputs!$F$31*12*(1+Inputs!$F$35)^(7-1) | K43: =$C$8*Inputs!$F$31*12*(1+Inputs!$F$35)^(8-1) | L43: =$C$8*Inputs!$F$31*12*(1+Inputs!$F$35)^(9-1) | M43: =$C$8*Inputs!$F$31*12*(1+Inputs!$F$35)^(10-1)
...

Sheet HYD_Base
A1: Hyderabad - base scenario - station model (all formulas)
A2: Green = link to Inputs, black = calculation. Change inputs on the Inputs sheet only.
A4: Configuration | C4: =Inputs!$C$4
A5: 60 kW DC chargers | C5: =INDEX(Inputs!$C$63:$C$65,MATCH(C4,Inputs!$A$63:$A$65,0))
A6: 120 kW DC chargers | C6: =INDEX(Inputs!$D$63:$D$65,MATCH(C4,Inputs!$A$63:$A$65,0))
A7: 7.4 kW AC chargers | C7: =INDEX(Inputs!$E$63:$E$65,MATCH(C4,Inputs!$A$63:$A$65,0))
A8: Total chargers | C8: =C5+C6+C7
A9: Total connected kW | C9: =C5*60+C6*120+C7*7.4
A10: CAPEX multiplier (scenario x control) | C10: =Inputs!$G$36*Inputs!$C$8
A11: Chargers (Rs) | C11: =(C5*Inputs!$C$50+C6*Inputs!$C$51+C7*Inputs!$C$52)*C10
A12: Grid connection work (Rs) | C12: =INDEX(Inputs!$G$63:$G$65,MATCH(C4,Inputs!$A$63:$A$65,0))*100000*C10*Inputs!$C$9
A13: Civil & installation (Rs) | C13: =((C5+C6)*Inputs!$C$53+C7*Inputs!$C$54)*C10
A14: Signage, software set-up, permits (Rs) | C14: =Inputs!$C$55+Inputs!$C$56+Inputs!$C$57
A15: Contingency (Rs) | C15: =SUM(C11:C14)*Inputs!$G$37
A16: TOTAL CAPEX (Rs) | C16: =SUM(C11:C15)
A17: Capacity, kWh/day (at max practical utilisation) | C17: =C9*Inputs!$G$39*24*Inputs!$G$40*Inputs!$G$38
A18: Energy if in use 24h, kWh/day (for utilisation %) | C18: =C9*Inputs!$G$39*24
A19: Fair share of public demand, kWh/day | C19: =Inputs!$G$15/Inputs!$G$16
A20: Steady demand year 1, kWh/day | C20: =C19*Inputs!$G$17*Inputs!$C$5
A21: Price net of GST year 1 (Rs/kWh) | C21: =Inputs!$G$21*Inputs!$C$6
A22: Electricity tariff year 1 (Rs/kWh) | C22: =Inputs!$G$23*Inputs!$C$7
A23: Fixed electricity charge (Rs/month) | C23: =IF(AND(TRUE,C9>150),C9/0.95*Inputs!$C$58+Inputs!$C$59,Inputs!$G$24)
A24: Host revenue share | C24: =IF(Inputs!$C$11="",Inputs!$G$27,Inputs!$C$11)
A25: Staff FTE | C25: =IF(Inputs!$C$10="",Inputs!$G$28,Inputs!$C$10)
A26: Discount rate (CAPM: Rf + beta x ERP) | C26: =IF(Inputs!$C$12="",Inputs!$G$44+Inputs!$G$46*Inputs!$G$45,Inputs!$C$12)
A27: Annual depreciation (Rs) | C27: =C16/Inputs!$G$42
A30: ANNUAL PROJECTION (Rs unless stated)
A31: Year | C31: 0 | D31: 1 | E31: 2 | F31: 3 | G31: 4 | H31: 5 | I31: 6 | J31: 7 | K31: 8 | L31: 9 | M31: 10
A32: Demand kWh/day | D32: =$C$20*(1+Inputs!$G$19)^(1-1)*Inputs!$G$18 | E32: =$C$20*(1+Inputs!$G$19)^(2-1) | F32: =$C$20*(1+Inputs!$G$19)^(3-1) | G32: =$C$20*(1+Inputs!$G$19)^(4-1) | H32: =$C$20*(1+Inputs!$G$19)^(5-1) | I32: =$C$20*(1+Inputs!$G$19)^(6-1) | J32: =$C$20*(1+Inputs!$G$19)^(7-1) | K32: =$C$20*(1+Inputs!$G$19)^(8-1) | L32: =$C$20*(1+Inputs!$G$19)^(9-1) | M32: =$C$20*(1+Inputs!$G$19)^(10-1)
A33: kWh sold per day | D33: =MIN(D32,$C$17) | E33: =MIN(E32,$C$17) | F33: =MIN(F32,$C$17) | G33: =MIN(G32,$C$17) | H33: =MIN(H32,$C$17) | I33: =MIN(I32,$C$17) | J33: =MIN(J32,$C$17) | K33: =MIN(K32,$C$17) | ... M33: =MIN(M32,$C$17)
A34: Sessions per day | D34: =D33/Inputs!$G$20 | E34: =E33/Inputs!$G$20 | F34: =F33/Inputs!$G$20 | G34: =G33/Inputs!$G$20 | H34: =H33/Inputs!$G$20 | I34: =I33/Inputs!$G$20 | J34: =J33/Inputs!$G$20 | K34: =K33/Inputs!$G$20 | ... M34: =M33/Inputs!$G$20
A35: Utilisation (% of hours) | D35: =D33/$C$18 | E35: =E33/$C$18 | F35: =F33/$C$18 | G35: =G33/$C$18 | H35: =H33/$C$18 | I35: =I33/$C$18 | J35: =J33/$C$18 | K35: =K33/$C$18 | ... M35: =M33/$C$18
A36: kWh sold per year | D36: =D33*365 | E36: =E33*365 | F36: =F33*365 | G36: =G33*365 | H36: =H33*365 | I36: =I33*365 | J36: =J33*365 | K36: =K33*365 | ... M36: =M33*365
A37: Revenue | D37: =D36*$C$21*(1+Inputs!$G$22)^(1-1) | E37: =E36*$C$21*(1+Inputs!$G$22)^(2-1) | F37: =F36*$C$21*(1+Inputs!$G$22)^(3-1) | G37: =G36*$C$21*(1+Inputs!$G$22)^(4-1) | H37: =H36*$C$21*(1+Inputs!$G$22)^(5-1) | I37: =I36*$C$21*(1+Inputs!$G$22)^(6-1) | J37: =J36*$C$21*(1+Inputs!$G$22)^(7-1) | K37: =K36*$C$21*(1+Inputs!$G$22)^(8-1) | L37: =L36*$C$21*(1+Inputs!$G$22)^(9-1) | M37: =M36*$C$21*(1+Inputs!$G$22)^(10-1)
A38: Electricity cost | D38: =(D36/(1-Inputs!$G$26)*$C$22+$C$23*12)*(1+Inputs!$G$25)^(1-1) | E38: =(E36/(1-Inputs!$G$26)*$C$22+$C$23*12)*(1+Inputs!$G$25)^(2-1) | F38: =(F36/(1-Inputs!$G$26)*$C$22+$C$23*12)*(1+Inputs!$G$25)^(3-1) | G38: =(G36/(1-Inputs!$G$26)*$C$22+$C$23*12)*(1+Inputs!$G$25)^(4-1) | H38: =(H36/(1-Inputs!$G$26)*$C$22+$C$23*12)*(1+Inputs!$G$25)^(5-1) | I38: =(I36/(1-Inputs!$G$26)*$C$22+$C$23*12)*(1+Inputs!$G$25)^(6-1) | J38: =(J36/(1-Inputs!$G$26)*$C$22+$C$23*12)*(1+Inputs!$G$25)^(7-1) | K38: =(K36/(1-Inputs!$G$26)*$C$22+$C$23*12)*(1+Inputs!$G$25)^(8-1) | L38: =(L36/(1-Inputs!$G$26)*$C$22+$C$23*12)*(1+Inputs!$G$25)^(9-1) | M38: =(M36/(1-Inputs!$G$26)*$C$22+$C$23*12)*(1+Inputs!$G$25)^(10-1)
A39: Gross profit | D39: =D37-D38 | E39: =E37-E38 | F39: =F37-F38 | G39: =G37-G38 | H39: =H37-H38 | I39: =I37-I38 | J39: =J37-J38 | K39: =K37-K38 | ... M39: =M37-M38
A40: Host revenue share | D40: =D37*$C$24 | E40: =E37*$C$24 | F40: =F37*$C$24 | G40: =G37*$C$24 | H40: =H37*$C$24 | I40: =I37*$C$24 | J40: =J37*$C$24 | K40: =K37*$C$24 | ... M40: =M37*$C$24
A41: Staff | D41: =$C$25*Inputs!$G$29*12*(1+Inputs!$G$35)^(1-1) | E41: =$C$25*Inputs!$G$29*12*(1+Inputs!$G$35)^(2-1) | F41: =$C$25*Inputs!$G$29*12*(1+Inputs!$G$35)^(3-1) | G41: =$C$25*Inputs!$G$29*12*(1+Inputs!$G$35)^(4-1) | H41: =$C$25*Inputs!$G$29*12*(1+Inputs!$G$35)^(5-1) | I41: =$C$25*Inputs!$G$29*12*(1+Inputs!$G$35)^(6-1) | J41: =$C$25*Inputs!$G$29*12*(1+Inputs!$G$35)^(7-1) | K41: =$C$25*Inputs!$G$29*12*(1+Inputs!$G$35)^(8-1) | L41: =$C$25*Inputs!$G$29*12*(1+Inputs!$G$35)^(9-1) | M41: =$C$25*Inputs!$G$29*12*(1+Inputs!$G$35)^(10-1)
A42: Maintenance | D42: =$C$11*Inputs!$G$30*(1+Inputs!$G$35)^(1-1) | E42: =$C$11*Inputs!$G$30*(1+Inputs!$G$35)^(2-1) | F42: =$C$11*Inputs!$G$30*(1+Inputs!$G$35)^(3-1) | G42: =$C$11*Inputs!$G$30*(1+Inputs!$G$35)^(4-1) | H42: =$C$11*Inputs!$G$30*(1+Inputs!$G$35)^(5-1) | I42: =$C$11*Inputs!$G$30*(1+Inputs!$G$35)^(6-1) | J42: =$C$11*Inputs!$G$30*(1+Inputs!$G$35)^(7-1) | K42: =$C$11*Inputs!$G$30*(1+Inputs!$G$35)^(8-1) | L42: =$C$11*Inputs!$G$30*(1+Inputs!$G$35)^(9-1) | M42: =$C$11*Inputs!$G$30*(1+Inputs!$G$35)^(10-1)
A43: Software / CMS | D43: =$C$8*Inputs!$G$31*12*(1+Inputs!$G$35)^(1-1) | E43: =$C$8*Inputs!$G$31*12*(1+Inputs!$G$35)^(2-1) | F43: =$C$8*Inputs!$G$31*12*(1+Inputs!$G$35)^(3-1) | G43: =$C$8*Inputs!$G$31*12*(1+Inputs!$G$35)^(4-1) | H43: =$C$8*Inputs!$G$31*12*(1+Inputs!$G$35)^(5-1) | I43: =$C$8*Inputs!$G$31*12*(1+Inputs!$G$35)^(6-1) | J43: =$C$8*Inputs!$G$31*12*(1+Inputs!$G$35)^(7-1) | K43: =$C$8*Inputs!$G$31*12*(1+Inputs!$G$35)^(8-1) | L43: =$C$8*Inputs!$G$31*12*(1+Inputs!$G$35)^(9-1) | M43: =$C$8*Inputs!$G$31*12*(1+Inputs!$G$35)^(10-1)
...

Sheet HYD_Aggr
A1: Hyderabad - aggressive scenario - station model (all formulas)
A2: Green = link to Inputs, black = calculation. Change inputs on the Inputs sheet only.
A4: Configuration | C4: =Inputs!$C$4
A5: 60 kW DC chargers | C5: =INDEX(Inputs!$C$63:$C$65,MATCH(C4,Inputs!$A$63:$A$65,0))
A6: 120 kW DC chargers | C6: =INDEX(Inputs!$D$63:$D$65,MATCH(C4,Inputs!$A$63:$A$65,0))
A7: 7.4 kW AC chargers | C7: =INDEX(Inputs!$E$63:$E$65,MATCH(C4,Inputs!$A$63:$A$65,0))
A8: Total chargers | C8: =C5+C6+C7
A9: Total connected kW | C9: =C5*60+C6*120+C7*7.4
A10: CAPEX multiplier (scenario x control) | C10: =Inputs!$H$36*Inputs!$C$8
A11: Chargers (Rs) | C11: =(C5*Inputs!$C$50+C6*Inputs!$C$51+C7*Inputs!$C$52)*C10
A12: Grid connection work (Rs) | C12: =INDEX(Inputs!$G$63:$G$65,MATCH(C4,Inputs!$A$63:$A$65,0))*100000*C10*Inputs!$C$9
A13: Civil & installation (Rs) | C13: =((C5+C6)*Inputs!$C$53+C7*Inputs!$C$54)*C10
A14: Signage, software set-up, permits (Rs) | C14: =Inputs!$C$55+Inputs!$C$56+Inputs!$C$57
A15: Contingency (Rs) | C15: =SUM(C11:C14)*Inputs!$H$37
A16: TOTAL CAPEX (Rs) | C16: =SUM(C11:C15)
A17: Capacity, kWh/day (at max practical utilisation) | C17: =C9*Inputs!$H$39*24*Inputs!$H$40*Inputs!$H$38
A18: Energy if in use 24h, kWh/day (for utilisation %) | C18: =C9*Inputs!$H$39*24
A19: Fair share of public demand, kWh/day | C19: =Inputs!$H$15/Inputs!$H$16
A20: Steady demand year 1, kWh/day | C20: =C19*Inputs!$H$17*Inputs!$C$5
A21: Price net of GST year 1 (Rs/kWh) | C21: =Inputs!$H$21*Inputs!$C$6
A22: Electricity tariff year 1 (Rs/kWh) | C22: =Inputs!$H$23*Inputs!$C$7
A23: Fixed electricity charge (Rs/month) | C23: =IF(AND(TRUE,C9>150),C9/0.95*Inputs!$C$58+Inputs!$C$59,Inputs!$H$24)
A24: Host revenue share | C24: =IF(Inputs!$C$11="",Inputs!$H$27,Inputs!$C$11)
A25: Staff FTE | C25: =IF(Inputs!$C$10="",Inputs!$H$28,Inputs!$C$10)
A26: Discount rate (CAPM: Rf + beta x ERP) | C26: =IF(Inputs!$C$12="",Inputs!$H$44+Inputs!$H$46*Inputs!$H$45,Inputs!$C$12)
A27: Annual depreciation (Rs) | C27: =C16/Inputs!$H$42
A30: ANNUAL PROJECTION (Rs unless stated)
A31: Year | C31: 0 | D31: 1 | E31: 2 | F31: 3 | G31: 4 | H31: 5 | I31: 6 | J31: 7 | K31: 8 | L31: 9 | M31: 10
A32: Demand kWh/day | D32: =$C$20*(1+Inputs!$H$19)^(1-1)*Inputs!$H$18 | E32: =$C$20*(1+Inputs!$H$19)^(2-1) | F32: =$C$20*(1+Inputs!$H$19)^(3-1) | G32: =$C$20*(1+Inputs!$H$19)^(4-1) | H32: =$C$20*(1+Inputs!$H$19)^(5-1) | I32: =$C$20*(1+Inputs!$H$19)^(6-1) | J32: =$C$20*(1+Inputs!$H$19)^(7-1) | K32: =$C$20*(1+Inputs!$H$19)^(8-1) | L32: =$C$20*(1+Inputs!$H$19)^(9-1) | M32: =$C$20*(1+Inputs!$H$19)^(10-1)
A33: kWh sold per day | D33: =MIN(D32,$C$17) | E33: =MIN(E32,$C$17) | F33: =MIN(F32,$C$17) | G33: =MIN(G32,$C$17) | H33: =MIN(H32,$C$17) | I33: =MIN(I32,$C$17) | J33: =MIN(J32,$C$17) | K33: =MIN(K32,$C$17) | ... M33: =MIN(M32,$C$17)
A34: Sessions per day | D34: =D33/Inputs!$H$20 | E34: =E33/Inputs!$H$20 | F34: =F33/Inputs!$H$20 | G34: =G33/Inputs!$H$20 | H34: =H33/Inputs!$H$20 | I34: =I33/Inputs!$H$20 | J34: =J33/Inputs!$H$20 | K34: =K33/Inputs!$H$20 | ... M34: =M33/Inputs!$H$20
A35: Utilisation (% of hours) | D35: =D33/$C$18 | E35: =E33/$C$18 | F35: =F33/$C$18 | G35: =G33/$C$18 | H35: =H33/$C$18 | I35: =I33/$C$18 | J35: =J33/$C$18 | K35: =K33/$C$18 | ... M35: =M33/$C$18
A36: kWh sold per year | D36: =D33*365 | E36: =E33*365 | F36: =F33*365 | G36: =G33*365 | H36: =H33*365 | I36: =I33*365 | J36: =J33*365 | K36: =K33*365 | ... M36: =M33*365
A37: Revenue | D37: =D36*$C$21*(1+Inputs!$H$22)^(1-1) | E37: =E36*$C$21*(1+Inputs!$H$22)^(2-1) | F37: =F36*$C$21*(1+Inputs!$H$22)^(3-1) | G37: =G36*$C$21*(1+Inputs!$H$22)^(4-1) | H37: =H36*$C$21*(1+Inputs!$H$22)^(5-1) | I37: =I36*$C$21*(1+Inputs!$H$22)^(6-1) | J37: =J36*$C$21*(1+Inputs!$H$22)^(7-1) | K37: =K36*$C$21*(1+Inputs!$H$22)^(8-1) | L37: =L36*$C$21*(1+Inputs!$H$22)^(9-1) | M37: =M36*$C$21*(1+Inputs!$H$22)^(10-1)
A38: Electricity cost | D38: =(D36/(1-Inputs!$H$26)*$C$22+$C$23*12)*(1+Inputs!$H$25)^(1-1) | E38: =(E36/(1-Inputs!$H$26)*$C$22+$C$23*12)*(1+Inputs!$H$25)^(2-1) | F38: =(F36/(1-Inputs!$H$26)*$C$22+$C$23*12)*(1+Inputs!$H$25)^(3-1) | G38: =(G36/(1-Inputs!$H$26)*$C$22+$C$23*12)*(1+Inputs!$H$25)^(4-1) | H38: =(H36/(1-Inputs!$H$26)*$C$22+$C$23*12)*(1+Inputs!$H$25)^(5-1) | I38: =(I36/(1-Inputs!$H$26)*$C$22+$C$23*12)*(1+Inputs!$H$25)^(6-1) | J38: =(J36/(1-Inputs!$H$26)*$C$22+$C$23*12)*(1+Inputs!$H$25)^(7-1) | K38: =(K36/(1-Inputs!$H$26)*$C$22+$C$23*12)*(1+Inputs!$H$25)^(8-1) | L38: =(L36/(1-Inputs!$H$26)*$C$22+$C$23*12)*(1+Inputs!$H$25)^(9-1) | M38: =(M36/(1-Inputs!$H$26)*$C$22+$C$23*12)*(1+Inputs!$H$25)^(10-1)
A39: Gross profit | D39: =D37-D38 | E39: =E37-E38 | F39: =F37-F38 | G39: =G37-G38 | H39: =H37-H38 | I39: =I37-I38 | J39: =J37-J38 | K39: =K37-K38 | ... M39: =M37-M38
A40: Host revenue share | D40: =D37*$C$24 | E40: =E37*$C$24 | F40: =F37*$C$24 | G40: =G37*$C$24 | H40: =H37*$C$24 | I40: =I37*$C$24 | J40: =J37*$C$24 | K40: =K37*$C$24 | ... M40: =M37*$C$24
A41: Staff | D41: =$C$25*Inputs!$H$29*12*(1+Inputs!$H$35)^(1-1) | E41: =$C$25*Inputs!$H$29*12*(1+Inputs!$H$35)^(2-1) | F41: =$C$25*Inputs!$H$29*12*(1+Inputs!$H$35)^(3-1) | G41: =$C$25*Inputs!$H$29*12*(1+Inputs!$H$35)^(4-1) | H41: =$C$25*Inputs!$H$29*12*(1+Inputs!$H$35)^(5-1) | I41: =$C$25*Inputs!$H$29*12*(1+Inputs!$H$35)^(6-1) | J41: =$C$25*Inputs!$H$29*12*(1+Inputs!$H$35)^(7-1) | K41: =$C$25*Inputs!$H$29*12*(1+Inputs!$H$35)^(8-1) | L41: =$C$25*Inputs!$H$29*12*(1+Inputs!$H$35)^(9-1) | M41: =$C$25*Inputs!$H$29*12*(1+Inputs!$H$35)^(10-1)
A42: Maintenance | D42: =$C$11*Inputs!$H$30*(1+Inputs!$H$35)^(1-1) | E42: =$C$11*Inputs!$H$30*(1+Inputs!$H$35)^(2-1) | F42: =$C$11*Inputs!$H$30*(1+Inputs!$H$35)^(3-1) | G42: =$C$11*Inputs!$H$30*(1+Inputs!$H$35)^(4-1) | H42: =$C$11*Inputs!$H$30*(1+Inputs!$H$35)^(5-1) | I42: =$C$11*Inputs!$H$30*(1+Inputs!$H$35)^(6-1) | J42: =$C$11*Inputs!$H$30*(1+Inputs!$H$35)^(7-1) | K42: =$C$11*Inputs!$H$30*(1+Inputs!$H$35)^(8-1) | L42: =$C$11*Inputs!$H$30*(1+Inputs!$H$35)^(9-1) | M42: =$C$11*Inputs!$H$30*(1+Inputs!$H$35)^(10-1)
A43: Software / CMS | D43: =$C$8*Inputs!$H$31*12*(1+Inputs!$H$35)^(1-1) | E43: =$C$8*Inputs!$H$31*12*(1+Inputs!$H$35)^(2-1) | F43: =$C$8*Inputs!$H$31*12*(1+Inputs!$H$35)^(3-1) | G43: =$C$8*Inputs!$H$31*12*(1+Inputs!$H$35)^(4-1) | H43: =$C$8*Inputs!$H$31*12*(1+Inputs!$H$35)^(5-1) | I43: =$C$8*Inputs!$H$31*12*(1+Inputs!$H$35)^(6-1) | J43: =$C$8*Inputs!$H$31*12*(1+Inputs!$H$35)^(7-1) | K43: =$C$8*Inputs!$H$31*12*(1+Inputs!$H$35)^(8-1) | L43: =$C$8*Inputs!$H$31*12*(1+Inputs!$H$35)^(9-1) | M43: =$C$8*Inputs!$H$31*12*(1+Inputs!$H$35)^(10-1)
...
